[2015-11-04 12:04:00 +0100] [1804] [INFO] Starting gunicorn 19.3.0
[2015-11-04 12:04:00 +0100] [1804] [INFO] Listening at: http://0.0.0.0:5000 (1804)
[2015-11-04 12:04:00 +0100] [1804] [INFO] Using worker: sync
[2015-11-04 12:04:00 +0100] [1807] [INFO] Booting worker with pid: 1807
[2015-11-04 12:04:00 +0100] [1807] [ERROR] Exception in worker process:
Traceback (most recent call last):
  File "/Library/Frameworks/Python.framework/Versions/3.5/lib/python3.5/site-packages/gunicorn/arbiter.py", line 507, in spawn_worker
    worker.init_process()
  File "/Library/Frameworks/Python.framework/Versions/3.5/lib/python3.5/site-packages/gunicorn/workers/base.py", line 118, in init_process
    self.wsgi = self.app.wsgi()
  File "/Library/Frameworks/Python.framework/Versions/3.5/lib/python3.5/site-packages/gunicorn/app/base.py", line 67, in wsgi
    self.callable = self.load()
  File "/Library/Frameworks/Python.framework/Versions/3.5/lib/python3.5/site-packages/gunicorn/app/wsgiapp.py", line 65, in load
    return self.load_wsgiapp()
  File "/Library/Frameworks/Python.framework/Versions/3.5/lib/python3.5/site-packages/gunicorn/app/wsgiapp.py", line 52, in load_wsgiapp
    return util.import_app(self.app_uri)
  File "/Library/Frameworks/Python.framework/Versions/3.5/lib/python3.5/site-packages/gunicorn/util.py", line 355, in import_app
    __import__(module)
ImportError: No module named 'hello'
Traceback (most recent call last):
  File "/Library/Frameworks/Python.framework/Versions/3.5/lib/python3.5/site-packages/gunicorn/arbiter.py", line 507, in spawn_worker
    worker.init_process()
  File "/Library/Frameworks/Python.framework/Versions/3.5/lib/python3.5/site-packages/gunicorn/workers/base.py", line 118, in init_process
    self.wsgi = self.app.wsgi()
  File "/Library/Frameworks/Python.framework/Versions/3.5/lib/python3.5/site-packages/gunicorn/app/base.py", line 67, in wsgi
    self.callable = self.load()
  File "/Library/Frameworks/Python.framework/Versions/3.5/lib/python3.5/site-packages/gunicorn/app/wsgiapp.py", line 65, in load
    return self.load_wsgiapp()
  File "/Library/Frameworks/Python.framework/Versions/3.5/lib/python3.5/site-packages/gunicorn/app/wsgiapp.py", line 52, in load_wsgiapp
    return util.import_app(self.app_uri)
  File "/Library/Frameworks/Python.framework/Versions/3.5/lib/python3.5/site-packages/gunicorn/util.py", line 355, in import_app
    __import__(module)
ImportError: No module named 'hello'
[2015-11-04 12:04:00 +0100] [1807] [INFO] Worker exiting (pid: 1807)
[2015-11-04 12:10:16 +0100] [1841] [INFO] Starting gunicorn 19.3.0
[2015-11-04 12:10:16 +0100] [1841] [INFO] Listening at: http://0.0.0.0:5000 (1841)
[2015-11-04 12:10:16 +0100] [1841] [INFO] Using worker: sync
[2015-11-04 12:10:16 +0100] [1844] [INFO] Booting worker with pid: 1844
[2015-11-04 12:10:16 +0100] [1844] [ERROR] Exception in worker process:
Traceback (most recent call last):
  File "/Library/Frameworks/Python.framework/Versions/3.5/lib/python3.5/site-packages/gunicorn/arbiter.py", line 507, in spawn_worker
    worker.init_process()
  File "/Library/Frameworks/Python.framework/Versions/3.5/lib/python3.5/site-packages/gunicorn/workers/base.py", line 118, in init_process
    self.wsgi = self.app.wsgi()
  File "/Library/Frameworks/Python.framework/Versions/3.5/lib/python3.5/site-packages/gunicorn/app/base.py", line 67, in wsgi
    self.callable = self.load()
  File "/Library/Frameworks/Python.framework/Versions/3.5/lib/python3.5/site-packages/gunicorn/app/wsgiapp.py", line 65, in load
    return self.load_wsgiapp()
  File "/Library/Frameworks/Python.framework/Versions/3.5/lib/python3.5/site-packages/gunicorn/app/wsgiapp.py", line 52, in load_wsgiapp
    return util.import_app(self.app_uri)
  File "/Library/Frameworks/Python.framework/Versions/3.5/lib/python3.5/site-packages/gunicorn/util.py", line 355, in import_app
    __import__(module)
ImportError: No module named 'hello'
Traceback (most recent call last):
  File "/Library/Frameworks/Python.framework/Versions/3.5/lib/python3.5/site-packages/gunicorn/arbiter.py", line 507, in spawn_worker
    worker.init_process()
  File "/Library/Frameworks/Python.framework/Versions/3.5/lib/python3.5/site-packages/gunicorn/workers/base.py", line 118, in init_process
    self.wsgi = self.app.wsgi()
  File "/Library/Frameworks/Python.framework/Versions/3.5/lib/python3.5/site-packages/gunicorn/app/base.py", line 67, in wsgi
    self.callable = self.load()
  File "/Library/Frameworks/Python.framework/Versions/3.5/lib/python3.5/site-packages/gunicorn/app/wsgiapp.py", line 65, in load
    return self.load_wsgiapp()
  File "/Library/Frameworks/Python.framework/Versions/3.5/lib/python3.5/site-packages/gunicorn/app/wsgiapp.py", line 52, in load_wsgiapp
    return util.import_app(self.app_uri)
  File "/Library/Frameworks/Python.framework/Versions/3.5/lib/python3.5/site-packages/gunicorn/util.py", line 355, in import_app
    __import__(module)
ImportError: No module named 'hello'
[2015-11-04 12:10:16 +0100] [1844] [INFO] Worker exiting (pid: 1844)
[2015-11-04 12:10:16 +0100] [1841] [INFO] Shutting down: Master
[2015-11-04 12:10:16 +0100] [1841] [INFO] Reason: Worker failed to boot.
[2015-11-04 12:10:48 +0100] [1855] [INFO] Starting gunicorn 19.3.0
[2015-11-04 12:10:48 +0100] [1855] [INFO] Listening at: http://0.0.0.0:5000 (1855)
[2015-11-04 12:10:48 +0100] [1855] [INFO] Using worker: sync
[2015-11-04 12:10:48 +0100] [1858] [INFO] Booting worker with pid: 1858
[2015-11-04 12:10:48 +0100] [1858] [ERROR] Exception in worker process:
Traceback (most recent call last):
  File "/Library/Frameworks/Python.framework/Versions/3.5/lib/python3.5/site-packages/gunicorn/arbiter.py", line 507, in spawn_worker
    worker.init_process()
  File "/Library/Frameworks/Python.framework/Versions/3.5/lib/python3.5/site-packages/gunicorn/workers/base.py", line 118, in init_process
    self.wsgi = self.app.wsgi()
  File "/Library/Frameworks/Python.framework/Versions/3.5/lib/python3.5/site-packages/gunicorn/app/base.py", line 67, in wsgi
    self.callable = self.load()
  File "/Library/Frameworks/Python.framework/Versions/3.5/lib/python3.5/site-packages/gunicorn/app/wsgiapp.py", line 65, in load
    return self.load_wsgiapp()
  File "/Library/Frameworks/Python.framework/Versions/3.5/lib/python3.5/site-packages/gunicorn/app/wsgiapp.py", line 52, in load_wsgiapp
    return util.import_app(self.app_uri)
  File "/Library/Frameworks/Python.framework/Versions/3.5/lib/python3.5/site-packages/gunicorn/util.py", line 355, in import_app
    __import__(module)
ImportError: No module named 'hello'
Traceback (most recent call last):
  File "/Library/Frameworks/Python.framework/Versions/3.5/lib/python3.5/site-packages/gunicorn/arbiter.py", line 507, in spawn_worker
    worker.init_process()
  File "/Library/Frameworks/Python.framework/Versions/3.5/lib/python3.5/site-packages/gunicorn/workers/base.py", line 118, in init_process
    self.wsgi = self.app.wsgi()
  File "/Library/Frameworks/Python.framework/Versions/3.5/lib/python3.5/site-packages/gunicorn/app/base.py", line 67, in wsgi
    self.callable = self.load()
  File "/Library/Frameworks/Python.framework/Versions/3.5/lib/python3.5/site-packages/gunicorn/app/wsgiapp.py", line 65, in load
    return self.load_wsgiapp()
  File "/Library/Frameworks/Python.framework/Versions/3.5/lib/python3.5/site-packages/gunicorn/app/wsgiapp.py", line 52, in load_wsgiapp
    return util.import_app(self.app_uri)
  File "/Library/Frameworks/Python.framework/Versions/3.5/lib/python3.5/site-packages/gunicorn/util.py", line 355, in import_app
    __import__(module)
ImportError: No module named 'hello'
[2015-11-04 12:10:48 +0100] [1858] [INFO] Worker exiting (pid: 1858)
[2015-11-04 12:10:48 +0100] [1855] [INFO] Shutting down: Master
[2015-11-04 12:10:48 +0100] [1855] [INFO] Reason: Worker failed to boot.
[2015-11-04 12:11:01 +0100] [1875] [INFO] Starting gunicorn 19.3.0
[2015-11-04 12:11:01 +0100] [1875] [INFO] Listening at: http://0.0.0.0:5000 (1875)
[2015-11-04 12:11:01 +0100] [1875] [INFO] Using worker: sync
[2015-11-04 12:11:01 +0100] [1878] [INFO] Booting worker with pid: 1878
[2015-11-04 12:11:01 +0100] [1878] [ERROR] Exception in worker process:
Traceback (most recent call last):
  File "/Library/Frameworks/Python.framework/Versions/3.5/lib/python3.5/site-packages/gunicorn/arbiter.py", line 507, in spawn_worker
    worker.init_process()
  File "/Library/Frameworks/Python.framework/Versions/3.5/lib/python3.5/site-packages/gunicorn/workers/base.py", line 118, in init_process
    self.wsgi = self.app.wsgi()
  File "/Library/Frameworks/Python.framework/Versions/3.5/lib/python3.5/site-packages/gunicorn/app/base.py", line 67, in wsgi
    self.callable = self.load()
  File "/Library/Frameworks/Python.framework/Versions/3.5/lib/python3.5/site-packages/gunicorn/app/wsgiapp.py", line 65, in load
    return self.load_wsgiapp()
  File "/Library/Frameworks/Python.framework/Versions/3.5/lib/python3.5/site-packages/gunicorn/app/wsgiapp.py", line 52, in load_wsgiapp
    return util.import_app(self.app_uri)
  File "/Library/Frameworks/Python.framework/Versions/3.5/lib/python3.5/site-packages/gunicorn/util.py", line 355, in import_app
    __import__(module)
ImportError: No module named 'hello'
Traceback (most recent call last):
  File "/Library/Frameworks/Python.framework/Versions/3.5/lib/python3.5/site-packages/gunicorn/arbiter.py", line 507, in spawn_worker
    worker.init_process()
  File "/Library/Frameworks/Python.framework/Versions/3.5/lib/python3.5/site-packages/gunicorn/workers/base.py", line 118, in init_process
    self.wsgi = self.app.wsgi()
  File "/Library/Frameworks/Python.framework/Versions/3.5/lib/python3.5/site-packages/gunicorn/app/base.py", line 67, in wsgi
    self.callable = self.load()
  File "/Library/Frameworks/Python.framework/Versions/3.5/lib/python3.5/site-packages/gunicorn/app/wsgiapp.py", line 65, in load
    return self.load_wsgiapp()
  File "/Library/Frameworks/Python.framework/Versions/3.5/lib/python3.5/site-packages/gunicorn/app/wsgiapp.py", line 52, in load_wsgiapp
    return util.import_app(self.app_uri)
  File "/Library/Frameworks/Python.framework/Versions/3.5/lib/python3.5/site-packages/gunicorn/util.py", line 355, in import_app
    __import__(module)
ImportError: No module named 'hello'
[2015-11-04 12:11:01 +0100] [1878] [INFO] Worker exiting (pid: 1878)
